-----------------------------------New Session-----------------------------------
2021-04-17 16:30:53,611 | INFO | discord.client | logging in using static token
2021-04-17 16:30:54,545 | INFO | discord.gateway | Shard ID None has sent the IDENTIFY payload.
2021-04-17 16:30:55,130 | INFO | discord.gateway | Shard ID None has connected to Gateway: ["gateway-prd-main-c5rj",{"micros":385878,"calls":["discord-sessions-prd-2-127",{"micros":384358,"calls":["start_session",{"micros":345003,"calls":["api-prd-main-f9dv",{"micros":341039,"calls":["get_user",{"micros":260705},"add_authorized_ip",{"micros":32305},"get_guilds",{"micros":6432},"coros_wait",{"micros":1}]}]},"guilds_connect",{"micros":10,"calls":[]},"presence_connect",{"micros":2485,"calls":[]}]}]}] (Session ID: f1436e8eeba9d63530f020b90086fb8b).
2021-04-17 16:30:57,144 | INFO | discord | Bot ready to use!
2021-04-17 16:31:00,053 | INFO | discord | Get mem from: 532157271531061255
2021-04-17 16:43:33,857 | INFO | discord.gateway | Websocket closed with 4003, attempting a reconnect.
2021-04-17 16:43:33,857 | INFO | discord.client | Got a request to RESUME the websocket.
2021-04-17 16:43:34,518 | INFO | discord.gateway | Shard ID None has sent the RESUME payload.
2021-04-17 16:43:34,717 | INFO | discord.gateway | Shard ID None session has been invalidated.
2021-04-17 16:43:34,918 | INFO | discord.client | Got a request to IDENTIFY the websocket.
2021-04-17 16:43:40,374 | INFO | discord.gateway | Shard ID None has sent the IDENTIFY payload.
2021-04-17 16:43:40,580 | INFO | discord.gateway | Websocket closed with 4004, cannot reconnect.
2021-04-17 16:43:40,585 | INFO | discord.client | Cleaning up tasks.
2021-04-17 16:43:40,585 | INFO | discord.client | Cleaning up after 1 tasks.
2021-04-17 16:43:40,586 | INFO | discord.client | All tasks finished cancelling.
2021-04-17 16:43:40,586 | INFO | discord.client | Closing the event loop.
-----------------------------------New Session-----------------------------------
2021-04-17 16:46:53,102 | INFO | discord.client | logging in using static token
2021-04-17 16:46:53,454 | INFO | discord.client | Cleaning up tasks.
2021-04-17 16:46:53,454 | INFO | discord.client | Cleaning up after 1 tasks.
2021-04-17 16:46:53,454 | INFO | discord.client | All tasks finished cancelling.
2021-04-17 16:46:53,454 | INFO | discord.client | Closing the event loop.
-----------------------------------New Session-----------------------------------
2021-04-17 16:48:04,341 | INFO | discord.client | logging in using static token
2021-04-17 16:48:05,320 | INFO | discord.gateway | Shard ID None has sent the IDENTIFY payload.
2021-04-17 16:48:05,595 | INFO | discord.gateway | Shard ID None has connected to Gateway: ["gateway-prd-main-pgf0",{"micros":71711,"calls":["discord-sessions-prd-2-63",{"micros":68520,"calls":["start_session",{"micros":47639,"calls":["api-prd-main-r04q",{"micros":42945,"calls":["get_user",{"micros":3948},"add_authorized_ip",{"micros":2881},"get_guilds",{"micros":10571},"coros_wait",{"micros":1}]}]},"guilds_connect",{"micros":2,"calls":[]},"presence_connect",{"micros":1,"calls":[]}]}]}] (Session ID: 81bdd1533059469a681abc8217deea3d).
2021-04-17 16:48:05,606 | WARNING | discord.state | GUILD_MEMBER_UPDATE referencing an unknown member ID: 824934127089745980. Discarding.
2021-04-17 16:48:07,608 | INFO | discord | Bot ready to use!
2021-04-17 16:48:10,386 | WARNING | discord | Command to test def sended
2021-04-17 16:48:35,627 | ERROR | discord | Bad argument error from: <@532157271531061255>
2021-04-17 16:49:15,202 | INFO | discord | Starting spam to id:<@!780798543622569984>, from: <@532157271531061255>
2021-04-17 16:49:25,286 | INFO | discord | Spam to id: <@!780798543622569984>
2021-04-17 16:49:28,185 | INFO | discord | Spammer stopped by: <@532157271531061255>
2021-04-17 16:50:01,804 | INFO | discord | Get mem from: 532157271531061255
-----------------------------------New Session-----------------------------------
2021-04-17 16:50:36,712 | INFO | discord.client | logging in using static token
2021-04-17 16:50:37,489 | INFO | discord.gateway | Shard ID None has sent the IDENTIFY payload.
2021-04-17 16:50:37,746 | INFO | discord.gateway | Shard ID None has connected to Gateway: ["gateway-prd-main-3ljd",{"micros":56201,"calls":["discord-sessions-prd-2-17",{"micros":54262,"calls":["start_session",{"micros":37108,"calls":["api-prd-main-znt9",{"micros":34023,"calls":["get_user",{"micros":3257},"add_authorized_ip",{"micros":3514},"get_guilds",{"micros":7159},"coros_wait",{"micros":1}]}]},"guilds_connect",{"micros":2,"calls":[]},"presence_connect",{"micros":16443,"calls":[]}]}]}] (Session ID: 480d893c598ff1b09d9baf248f62cacb).
2021-04-17 16:50:39,762 | INFO | discord | Bot ready to use!
2021-04-17 17:08:03,347 | INFO | discord.client | Got a request to RESUME the websocket.
2021-04-17 17:08:04,044 | INFO | discord.gateway | Shard ID None has sent the RESUME payload.
2021-04-17 17:08:04,253 | INFO | discord.gateway | Shard ID None has successfully RESUMED session 480d893c598ff1b09d9baf248f62cacb under trace ["gateway-prd-main-7w7j",{"micros":2521,"calls":["discord-sessions-prd-2-17",{"micros":14}]}].
2021-04-17 19:42:58,205 | INFO | discord.client | Got a request to RESUME the websocket.
2021-04-17 19:42:58,888 | INFO | discord.gateway | Shard ID None has sent the RESUME payload.
2021-04-17 19:42:59,090 | INFO | discord.gateway | Shard ID None has successfully RESUMED session 480d893c598ff1b09d9baf248f62cacb under trace ["gateway-prd-main-x47s",{"micros":2757,"calls":["discord-sessions-prd-2-17",{"micros":12}]}].
2021-04-17 20:07:49,876 | INFO | discord | Starting spam to id:<@!625847518181195799>, from: <@532157271531061255>
2021-04-17 20:07:59,639 | INFO | discord | Spam to id: <@!625847518181195799>
2021-04-17 20:08:09,904 | INFO | discord | Spam to id: <@!625847518181195799>
2021-04-17 20:08:20,188 | INFO | discord | Spam to id: <@!625847518181195799>
2021-04-17 20:08:30,553 | INFO | discord | Spam to id: <@!625847518181195799>
2021-04-17 20:08:40,909 | INFO | discord | Spam to id: <@!625847518181195799>
2021-04-17 20:08:51,351 | INFO | discord | Spam to id: <@!625847518181195799>
2021-04-17 20:09:01,754 | INFO | discord | Spam to id: <@!625847518181195799>
2021-04-17 20:09:12,072 | INFO | discord | Spam to id: <@!625847518181195799>
2021-04-17 20:09:22,390 | INFO | discord | Spam to id: <@!625847518181195799>
2021-04-17 20:09:32,716 | INFO | discord | Spam to id: <@!625847518181195799>
2021-04-17 20:09:42,990 | INFO | discord | Spam to id: <@!625847518181195799>
2021-04-17 20:09:53,270 | INFO | discord | Spam to id: <@!625847518181195799>
2021-04-17 20:10:03,619 | INFO | discord | Spam to id: <@!625847518181195799>
2021-04-17 20:10:14,003 | INFO | discord | Spam to id: <@!625847518181195799>
2021-04-17 20:10:24,341 | INFO | discord | Spam to id: <@!625847518181195799>
2021-04-17 20:10:34,612 | INFO | discord | Spam to id: <@!625847518181195799>
2021-04-17 20:10:44,890 | INFO | discord | Spam to id: <@!625847518181195799>
2021-04-17 20:10:53,613 | ERROR | discord | Command not found from: <@532157271531061255>
2021-04-17 20:10:55,311 | INFO | discord | Spam to id: <@!625847518181195799>
2021-04-17 20:11:00,257 | WARNING | discord.http | We are being rate limited. Retrying in 3.22 seconds. Handled under the bucket "731080188045295678:None:/channels/{channel_id}/messages/{message_id}"
2021-04-17 20:11:05,530 | WARNING | discord.http | We are being rate limited. Retrying in 3.17 seconds. Handled under the bucket "731080188045295678:None:/channels/{channel_id}/messages/{message_id}"
2021-04-17 20:11:10,748 | WARNING | discord.http | We are being rate limited. Retrying in 3.19 seconds. Handled under the bucket "731080188045295678:None:/channels/{channel_id}/messages/{message_id}"
2021-04-17 20:11:14,658 | INFO | discord | Spammer stopped by: <@532157271531061255>
2021-04-17 22:30:10,863 | INFO | discord.voice_client | Connecting to voice...
2021-04-17 22:30:10,864 | INFO | discord.voice_client | Starting voice handshake...
2021-04-17 22:30:11,204 | INFO | discord.voice_client | Voice handshake complete. Endpoint found russia6294.discord.media (IP: None)
2021-04-17 22:30:11,681 | INFO | discord.gateway | selected the voice protocol for use (xsalsa20_poly1305_lite)
2021-04-17 22:30:11,738 | INFO | discord.gateway | received secret key for voice connection
2021-04-17 22:30:15,176 | INFO | discord.player | Preparing to terminate ffmpeg process 13480.
2021-04-17 22:30:15,176 | INFO | discord.player | ffmpeg process 13480 successfully terminated with return code of 0.
2021-04-17 22:30:17,177 | INFO | discord.voice_client | Disconnecting from voice normally, close code 4014.
2021-04-17 22:30:17,178 | INFO | discord.voice_client | The voice handshake is being terminated for Channel ID 787194285745373244 (Guild ID 731080187596374087)
2021-04-17 22:30:17,178 | INFO | discord.voice_client | The voice client has been removed for Channel ID 787194285745373244 (Guild ID 731080187596374087)
2021-04-17 22:30:17,224 | INFO | discord | <@532157271531061255> calls AMOGUS!1!3qw!f7eds
2021-04-17 22:56:18,772 | INFO | discord.client | Got a request to RESUME the websocket.
2021-04-17 22:56:19,476 | INFO | discord.gateway | Shard ID None has sent the RESUME payload.
2021-04-17 22:56:19,671 | INFO | discord.gateway | Shard ID None has successfully RESUMED session 480d893c598ff1b09d9baf248f62cacb under trace ["gateway-prd-main-bkdx",{"micros":2284,"calls":["discord-sessions-prd-2-17",{"micros":16}]}].
2021-04-17 23:15:24,996 | INFO | discord.client | Got a request to RESUME the websocket.
2021-04-17 23:15:25,591 | INFO | discord.gateway | Shard ID None has sent the RESUME payload.
2021-04-17 23:15:25,791 | INFO | discord.gateway | Shard ID None has successfully RESUMED session 480d893c598ff1b09d9baf248f62cacb under trace ["gateway-prd-main-n5rg",{"micros":5209,"calls":["discord-sessions-prd-2-17",{"micros":13}]}].
2021-04-17 23:49:01,538 | INFO | discord.voice_client | Connecting to voice...
2021-04-17 23:49:01,538 | INFO | discord.voice_client | Starting voice handshake...
2021-04-17 23:49:01,879 | INFO | discord.voice_client | Voice handshake complete. Endpoint found russia9978.discord.media (IP: None)
2021-04-17 23:49:02,307 | INFO | discord.gateway | selected the voice protocol for use (xsalsa20_poly1305_lite)
2021-04-17 23:49:02,353 | INFO | discord.gateway | received secret key for voice connection
2021-04-17 23:49:04,672 | INFO | discord.player | Preparing to terminate ffmpeg process 14296.
2021-04-17 23:49:04,672 | INFO | discord.player | ffmpeg process 14296 successfully terminated with return code of 0.
2021-04-17 23:49:04,861 | INFO | discord.voice_client | The voice handshake is being terminated for Channel ID 814716051652345928 (Guild ID 731080187596374087)
2021-04-17 23:49:04,861 | INFO | discord.voice_client | The voice client has been removed for Channel ID 814716051652345928 (Guild ID 731080187596374087)
2021-04-17 23:49:04,861 | INFO | discord | <@625847518181195799> killed Кабан Раздора
2021-04-17 23:49:04,862 | INFO | discord.voice_client | Disconnecting from voice normally, close code 1000.
2021-04-17 23:50:38,634 | INFO | discord.voice_client | Connecting to voice...
2021-04-17 23:50:38,634 | INFO | discord.voice_client | Starting voice handshake...
2021-04-17 23:50:38,980 | INFO | discord.voice_client | Voice handshake complete. Endpoint found russia9978.discord.media (IP: None)
2021-04-17 23:50:39,349 | INFO | discord.gateway | selected the voice protocol for use (xsalsa20_poly1305_lite)
2021-04-17 23:50:39,403 | INFO | discord.gateway | received secret key for voice connection
2021-04-17 23:50:41,308 | INFO | discord.player | Preparing to terminate ffmpeg process 10796.
2021-04-17 23:50:41,308 | INFO | discord.player | ffmpeg process 10796 successfully terminated with return code of 0.
2021-04-17 23:50:41,373 | INFO | discord.voice_client | The voice handshake is being terminated for Channel ID 814716051652345928 (Guild ID 731080187596374087)
2021-04-17 23:50:41,373 | INFO | discord.voice_client | The voice client has been removed for Channel ID 814716051652345928 (Guild ID 731080187596374087)
2021-04-17 23:50:41,374 | INFO | discord | <@475597250819784704> killed Кабан Раздора
2021-04-17 23:50:41,374 | INFO | discord.voice_client | Disconnecting from voice normally, close code 1000.
2021-04-17 23:53:27,233 | INFO | discord.client | Got a request to RESUME the websocket.
2021-04-17 23:53:27,918 | INFO | discord.gateway | Shard ID None has sent the RESUME payload.
2021-04-17 23:53:28,123 | INFO | discord.gateway | Shard ID None has successfully RESUMED session 480d893c598ff1b09d9baf248f62cacb under trace ["gateway-prd-main-v2qn",{"micros":10042,"calls":["discord-sessions-prd-2-17",{"micros":14}]}].
2021-04-18 00:09:22,583 | INFO | discord.gateway | Websocket closed with 1006, attempting a reconnect.
2021-04-18 00:09:22,584 | INFO | discord.client | Got a request to RESUME the websocket.
2021-04-18 00:09:22,604 | ERROR | discord.client | Attempting a reconnect in 0.31s
Traceback (most recent call last):
  File "C:\Users\glebg\AppData\Roaming\Python\Python38\site-packages\aiohttp\connector.py", line 964, in _create_direct_connection
    hosts = await asyncio.shield(self._resolve_host(
  File "C:\Users\glebg\AppData\Roaming\Python\Python38\site-packages\aiohttp\connector.py", line 829, in _resolve_host
    addrs = await \
  File "C:\Users\glebg\AppData\Roaming\Python\Python38\site-packages\aiohttp\resolver.py", line 29, in resolve
    infos = await self._loop.getaddrinfo(
  File "C:\Users\glebg\AppData\Local\Programs\Python\Python38-32\lib\asyncio\base_events.py", line 825, in getaddrinfo
    return await self.run_in_executor(
  File "C:\Users\glebg\AppData\Local\Programs\Python\Python38-32\lib\concurrent\futures\thread.py", line 57, in run
    result = self.fn(*self.args, **self.kwargs)
  File "C:\Users\glebg\AppData\Local\Programs\Python\Python38-32\lib\socket.py", line 918, in getaddrinfo
    for res in _socket.getaddrinfo(host, port, family, type, proto, flags):
socket.gaierror: [Errno 11001] getaddrinfo failed

The above exception was the direct cause of the following exception:

Traceback (most recent call last):
  File "C:\Users\glebg\AppData\Roaming\Python\Python38\site-packages\discord\client.py", line 521, in connect
    self.ws = await asyncio.wait_for(coro, timeout=60.0)
  File "C:\Users\glebg\AppData\Local\Programs\Python\Python38-32\lib\asyncio\tasks.py", line 483, in wait_for
    return fut.result()
  File "C:\Users\glebg\AppData\Roaming\Python\Python38\site-packages\discord\gateway.py", line 254, in from_client
    gateway = gateway or await client.http.get_gateway()
  File "C:\Users\glebg\AppData\Roaming\Python\Python38\site-packages\discord\http.py", line 907, in get_gateway
    data = await self.request(Route('GET', '/gateway'))
  File "C:\Users\glebg\AppData\Roaming\Python\Python38\site-packages\discord\http.py", line 185, in request
    async with self.__session.request(method, url, **kwargs) as r:
  File "C:\Users\glebg\AppData\Roaming\Python\Python38\site-packages\aiohttp\client.py", line 1012, in __aenter__
    self._resp = await self._coro
  File "C:\Users\glebg\AppData\Roaming\Python\Python38\site-packages\aiohttp\client.py", line 480, in _request
    conn = await self._connector.connect(
  File "C:\Users\glebg\AppData\Roaming\Python\Python38\site-packages\aiohttp\connector.py", line 523, in connect
    proto = await self._create_connection(req, traces, timeout)
  File "C:\Users\glebg\AppData\Roaming\Python\Python38\site-packages\aiohttp\connector.py", line 858, in _create_connection
    _, proto = await self._create_direct_connection(
  File "C:\Users\glebg\AppData\Roaming\Python\Python38\site-packages\aiohttp\connector.py", line 971, in _create_direct_connection
    raise ClientConnectorError(req.connection_key, exc) from exc
aiohttp.client_exceptions.ClientConnectorError: Cannot connect to host discord.com:443 ssl:default [getaddrinfo failed]
2021-04-18 00:09:22,946 | ERROR | discord.client | Attempting a reconnect in 3.99s
Traceback (most recent call last):
  File "C:\Users\glebg\AppData\Roaming\Python\Python38\site-packages\aiohttp\connector.py", line 964, in _create_direct_connection
    hosts = await asyncio.shield(self._resolve_host(
  File "C:\Users\glebg\AppData\Roaming\Python\Python38\site-packages\aiohttp\connector.py", line 829, in _resolve_host
    addrs = await \
  File "C:\Users\glebg\AppData\Roaming\Python\Python38\site-packages\aiohttp\resolver.py", line 29, in resolve
    infos = await self._loop.getaddrinfo(
  File "C:\Users\glebg\AppData\Local\Programs\Python\Python38-32\lib\asyncio\base_events.py", line 825, in getaddrinfo
    return await self.run_in_executor(
  File "C:\Users\glebg\AppData\Local\Programs\Python\Python38-32\lib\concurrent\futures\thread.py", line 57, in run
    result = self.fn(*self.args, **self.kwargs)
  File "C:\Users\glebg\AppData\Local\Programs\Python\Python38-32\lib\socket.py", line 918, in getaddrinfo
    for res in _socket.getaddrinfo(host, port, family, type, proto, flags):
socket.gaierror: [Errno 11001] getaddrinfo failed

The above exception was the direct cause of the following exception:

Traceback (most recent call last):
  File "C:\Users\glebg\AppData\Roaming\Python\Python38\site-packages\discord\client.py", line 521, in connect
    self.ws = await asyncio.wait_for(coro, timeout=60.0)
  File "C:\Users\glebg\AppData\Local\Programs\Python\Python38-32\lib\asyncio\tasks.py", line 483, in wait_for
    return fut.result()
  File "C:\Users\glebg\AppData\Roaming\Python\Python38\site-packages\discord\gateway.py", line 254, in from_client
    gateway = gateway or await client.http.get_gateway()
  File "C:\Users\glebg\AppData\Roaming\Python\Python38\site-packages\discord\http.py", line 907, in get_gateway
    data = await self.request(Route('GET', '/gateway'))
  File "C:\Users\glebg\AppData\Roaming\Python\Python38\site-packages\discord\http.py", line 185, in request
    async with self.__session.request(method, url, **kwargs) as r:
  File "C:\Users\glebg\AppData\Roaming\Python\Python38\site-packages\aiohttp\client.py", line 1012, in __aenter__
    self._resp = await self._coro
  File "C:\Users\glebg\AppData\Roaming\Python\Python38\site-packages\aiohttp\client.py", line 480, in _request
    conn = await self._connector.connect(
  File "C:\Users\glebg\AppData\Roaming\Python\Python38\site-packages\aiohttp\connector.py", line 523, in connect
    proto = await self._create_connection(req, traces, timeout)
  File "C:\Users\glebg\AppData\Roaming\Python\Python38\site-packages\aiohttp\connector.py", line 858, in _create_connection
    _, proto = await self._create_direct_connection(
  File "C:\Users\glebg\AppData\Roaming\Python\Python38\site-packages\aiohttp\connector.py", line 971, in _create_direct_connection
    raise ClientConnectorError(req.connection_key, exc) from exc
aiohttp.client_exceptions.ClientConnectorError: Cannot connect to host discord.com:443 ssl:default [getaddrinfo failed]
2021-04-18 00:09:26,938 | ERROR | discord.client | Attempting a reconnect in 2.67s
Traceback (most recent call last):
  File "C:\Users\glebg\AppData\Roaming\Python\Python38\site-packages\aiohttp\connector.py", line 964, in _create_direct_connection
    hosts = await asyncio.shield(self._resolve_host(
  File "C:\Users\glebg\AppData\Roaming\Python\Python38\site-packages\aiohttp\connector.py", line 829, in _resolve_host
    addrs = await \
  File "C:\Users\glebg\AppData\Roaming\Python\Python38\site-packages\aiohttp\resolver.py", line 29, in resolve
    infos = await self._loop.getaddrinfo(
  File "C:\Users\glebg\AppData\Local\Programs\Python\Python38-32\lib\asyncio\base_events.py", line 825, in getaddrinfo
    return await self.run_in_executor(
  File "C:\Users\glebg\AppData\Local\Programs\Python\Python38-32\lib\concurrent\futures\thread.py", line 57, in run
    result = self.fn(*self.args, **self.kwargs)
  File "C:\Users\glebg\AppData\Local\Programs\Python\Python38-32\lib\socket.py", line 918, in getaddrinfo
    for res in _socket.getaddrinfo(host, port, family, type, proto, flags):
socket.gaierror: [Errno 11001] getaddrinfo failed

The above exception was the direct cause of the following exception:

Traceback (most recent call last):
  File "C:\Users\glebg\AppData\Roaming\Python\Python38\site-packages\discord\client.py", line 521, in connect
    self.ws = await asyncio.wait_for(coro, timeout=60.0)
  File "C:\Users\glebg\AppData\Local\Programs\Python\Python38-32\lib\asyncio\tasks.py", line 483, in wait_for
    return fut.result()
  File "C:\Users\glebg\AppData\Roaming\Python\Python38\site-packages\discord\gateway.py", line 254, in from_client
    gateway = gateway or await client.http.get_gateway()
  File "C:\Users\glebg\AppData\Roaming\Python\Python38\site-packages\discord\http.py", line 907, in get_gateway
    data = await self.request(Route('GET', '/gateway'))
  File "C:\Users\glebg\AppData\Roaming\Python\Python38\site-packages\discord\http.py", line 185, in request
    async with self.__session.request(method, url, **kwargs) as r:
  File "C:\Users\glebg\AppData\Roaming\Python\Python38\site-packages\aiohttp\client.py", line 1012, in __aenter__
    self._resp = await self._coro
  File "C:\Users\glebg\AppData\Roaming\Python\Python38\site-packages\aiohttp\client.py", line 480, in _request
    conn = await self._connector.connect(
  File "C:\Users\glebg\AppData\Roaming\Python\Python38\site-packages\aiohttp\connector.py", line 523, in connect
    proto = await self._create_connection(req, traces, timeout)
  File "C:\Users\glebg\AppData\Roaming\Python\Python38\site-packages\aiohttp\connector.py", line 858, in _create_connection
    _, proto = await self._create_direct_connection(
  File "C:\Users\glebg\AppData\Roaming\Python\Python38\site-packages\aiohttp\connector.py", line 971, in _create_direct_connection
    raise ClientConnectorError(req.connection_key, exc) from exc
aiohttp.client_exceptions.ClientConnectorError: Cannot connect to host discord.com:443 ssl:default [getaddrinfo failed]
2021-04-18 00:09:29,611 | ERROR | discord.client | Attempting a reconnect in 0.02s
Traceback (most recent call last):
  File "C:\Users\glebg\AppData\Roaming\Python\Python38\site-packages\aiohttp\connector.py", line 964, in _create_direct_connection
    hosts = await asyncio.shield(self._resolve_host(
  File "C:\Users\glebg\AppData\Roaming\Python\Python38\site-packages\aiohttp\connector.py", line 829, in _resolve_host
    addrs = await \
  File "C:\Users\glebg\AppData\Roaming\Python\Python38\site-packages\aiohttp\resolver.py", line 29, in resolve
    infos = await self._loop.getaddrinfo(
  File "C:\Users\glebg\AppData\Local\Programs\Python\Python38-32\lib\asyncio\base_events.py", line 825, in getaddrinfo
    return await self.run_in_executor(
  File "C:\Users\glebg\AppData\Local\Programs\Python\Python38-32\lib\concurrent\futures\thread.py", line 57, in run
    result = self.fn(*self.args, **self.kwargs)
  File "C:\Users\glebg\AppData\Local\Programs\Python\Python38-32\lib\socket.py", line 918, in getaddrinfo
    for res in _socket.getaddrinfo(host, port, family, type, proto, flags):
socket.gaierror: [Errno 11001] getaddrinfo failed

The above exception was the direct cause of the following exception:

Traceback (most recent call last):
  File "C:\Users\glebg\AppData\Roaming\Python\Python38\site-packages\discord\client.py", line 521, in connect
    self.ws = await asyncio.wait_for(coro, timeout=60.0)
  File "C:\Users\glebg\AppData\Local\Programs\Python\Python38-32\lib\asyncio\tasks.py", line 483, in wait_for
    return fut.result()
  File "C:\Users\glebg\AppData\Roaming\Python\Python38\site-packages\discord\gateway.py", line 254, in from_client
    gateway = gateway or await client.http.get_gateway()
  File "C:\Users\glebg\AppData\Roaming\Python\Python38\site-packages\discord\http.py", line 907, in get_gateway
    data = await self.request(Route('GET', '/gateway'))
  File "C:\Users\glebg\AppData\Roaming\Python\Python38\site-packages\discord\http.py", line 185, in request
    async with self.__session.request(method, url, **kwargs) as r:
  File "C:\Users\glebg\AppData\Roaming\Python\Python38\site-packages\aiohttp\client.py", line 1012, in __aenter__
    self._resp = await self._coro
  File "C:\Users\glebg\AppData\Roaming\Python\Python38\site-packages\aiohttp\client.py", line 480, in _request
    conn = await self._connector.connect(
  File "C:\Users\glebg\AppData\Roaming\Python\Python38\site-packages\aiohttp\connector.py", line 523, in connect
    proto = await self._create_connection(req, traces, timeout)
  File "C:\Users\glebg\AppData\Roaming\Python\Python38\site-packages\aiohttp\connector.py", line 858, in _create_connection
    _, proto = await self._create_direct_connection(
  File "C:\Users\glebg\AppData\Roaming\Python\Python38\site-packages\aiohttp\connector.py", line 971, in _create_direct_connection
    raise ClientConnectorError(req.connection_key, exc) from exc
aiohttp.client_exceptions.ClientConnectorError: Cannot connect to host discord.com:443 ssl:default [getaddrinfo failed]
2021-04-18 00:09:29,631 | ERROR | discord.client | Attempting a reconnect in 26.98s
Traceback (most recent call last):
  File "C:\Users\glebg\AppData\Roaming\Python\Python38\site-packages\aiohttp\connector.py", line 964, in _create_direct_connection
    hosts = await asyncio.shield(self._resolve_host(
  File "C:\Users\glebg\AppData\Roaming\Python\Python38\site-packages\aiohttp\connector.py", line 829, in _resolve_host
    addrs = await \
  File "C:\Users\glebg\AppData\Roaming\Python\Python38\site-packages\aiohttp\resolver.py", line 29, in resolve
    infos = await self._loop.getaddrinfo(
  File "C:\Users\glebg\AppData\Local\Programs\Python\Python38-32\lib\asyncio\base_events.py", line 825, in getaddrinfo
    return await self.run_in_executor(
  File "C:\Users\glebg\AppData\Local\Programs\Python\Python38-32\lib\concurrent\futures\thread.py", line 57, in run
    result = self.fn(*self.args, **self.kwargs)
  File "C:\Users\glebg\AppData\Local\Programs\Python\Python38-32\lib\socket.py", line 918, in getaddrinfo
    for res in _socket.getaddrinfo(host, port, family, type, proto, flags):
socket.gaierror: [Errno 11001] getaddrinfo failed

The above exception was the direct cause of the following exception:

Traceback (most recent call last):
  File "C:\Users\glebg\AppData\Roaming\Python\Python38\site-packages\discord\client.py", line 521, in connect
    self.ws = await asyncio.wait_for(coro, timeout=60.0)
  File "C:\Users\glebg\AppData\Local\Programs\Python\Python38-32\lib\asyncio\tasks.py", line 483, in wait_for
    return fut.result()
  File "C:\Users\glebg\AppData\Roaming\Python\Python38\site-packages\discord\gateway.py", line 254, in from_client
    gateway = gateway or await client.http.get_gateway()
  File "C:\Users\glebg\AppData\Roaming\Python\Python38\site-packages\discord\http.py", line 907, in get_gateway
    data = await self.request(Route('GET', '/gateway'))
  File "C:\Users\glebg\AppData\Roaming\Python\Python38\site-packages\discord\http.py", line 185, in request
    async with self.__session.request(method, url, **kwargs) as r:
  File "C:\Users\glebg\AppData\Roaming\Python\Python38\site-packages\aiohttp\client.py", line 1012, in __aenter__
    self._resp = await self._coro
  File "C:\Users\glebg\AppData\Roaming\Python\Python38\site-packages\aiohttp\client.py", line 480, in _request
    conn = await self._connector.connect(
  File "C:\Users\glebg\AppData\Roaming\Python\Python38\site-packages\aiohttp\connector.py", line 523, in connect
    proto = await self._create_connection(req, traces, timeout)
  File "C:\Users\glebg\AppData\Roaming\Python\Python38\site-packages\aiohttp\connector.py", line 858, in _create_connection
    _, proto = await self._create_direct_connection(
  File "C:\Users\glebg\AppData\Roaming\Python\Python38\site-packages\aiohttp\connector.py", line 971, in _create_direct_connection
    raise ClientConnectorError(req.connection_key, exc) from exc
aiohttp.client_exceptions.ClientConnectorError: Cannot connect to host discord.com:443 ssl:default [getaddrinfo failed]
2021-04-18 11:15:28,008 | INFO | discord.gateway | Shard ID None has sent the RESUME payload.
2021-04-18 11:15:28,200 | INFO | discord.gateway | Shard ID None session has been invalidated.
2021-04-18 11:15:28,391 | INFO | discord.client | Got a request to IDENTIFY the websocket.
2021-04-18 11:15:33,805 | INFO | discord.gateway | Shard ID None has sent the IDENTIFY payload.
2021-04-18 11:15:34,086 | INFO | discord.gateway | Shard ID None has connected to Gateway: ["gateway-prd-main-77sw",{"micros":90596,"calls":["discord-sessions-prd-2-86",{"micros":89015,"calls":["start_session",{"micros":60905,"calls":["api-prd-main-2n5c",{"micros":57894,"calls":["get_user",{"micros":6673},"add_authorized_ip",{"micros":6286},"get_guilds",{"micros":8702},"coros_wait",{"micros":1}]}]},"guilds_connect",{"micros":2,"calls":[]},"presence_connect",{"micros":12750,"calls":[]}]}]}] (Session ID: 71a74b3ff36886157af3be96707f7aee).
2021-04-18 11:15:36,109 | INFO | discord | Bot ready to use!
2021-04-18 12:51:06,593 | INFO | discord.client | Got a request to RESUME the websocket.
2021-04-18 12:51:07,274 | INFO | discord.gateway | Shard ID None has sent the RESUME payload.
2021-04-18 12:51:07,472 | INFO | discord.gateway | Shard ID None has successfully RESUMED session 71a74b3ff36886157af3be96707f7aee under trace ["gateway-prd-main-pgf0",{"micros":1322,"calls":["discord-sessions-prd-2-86",{"micros":17}]}].
2021-04-18 14:29:27,194 | WARNING | discord | Command to test def sended
2021-04-18 14:55:21,840 | INFO | discord.client | Got a request to RESUME the websocket.
2021-04-18 14:55:22,555 | INFO | discord.gateway | Shard ID None has sent the RESUME payload.
2021-04-18 14:55:22,754 | INFO | discord.gateway | Shard ID None has successfully RESUMED session 71a74b3ff36886157af3be96707f7aee under trace ["gateway-prd-main-x9sf",{"micros":4925,"calls":["discord-sessions-prd-2-86",{"micros":12}]}].
2021-04-18 17:32:34,449 | INFO | discord.gateway | Websocket closed with 1006, attempting a reconnect.
2021-04-18 17:32:34,450 | INFO | discord.client | Got a request to RESUME the websocket.
2021-04-18 17:32:34,491 | ERROR | discord.client | Attempting a reconnect in 1.25s
Traceback (most recent call last):
  File "C:\Users\glebg\AppData\Roaming\Python\Python38\site-packages\aiohttp\connector.py", line 964, in _create_direct_connection
    hosts = await asyncio.shield(self._resolve_host(
  File "C:\Users\glebg\AppData\Roaming\Python\Python38\site-packages\aiohttp\connector.py", line 829, in _resolve_host
    addrs = await \
  File "C:\Users\glebg\AppData\Roaming\Python\Python38\site-packages\aiohttp\resolver.py", line 29, in resolve
    infos = await self._loop.getaddrinfo(
  File "C:\Users\glebg\AppData\Local\Programs\Python\Python38-32\lib\asyncio\base_events.py", line 825, in getaddrinfo
    return await self.run_in_executor(
  File "C:\Users\glebg\AppData\Local\Programs\Python\Python38-32\lib\concurrent\futures\thread.py", line 57, in run
    result = self.fn(*self.args, **self.kwargs)
  File "C:\Users\glebg\AppData\Local\Programs\Python\Python38-32\lib\socket.py", line 918, in getaddrinfo
    for res in _socket.getaddrinfo(host, port, family, type, proto, flags):
socket.gaierror: [Errno 11001] getaddrinfo failed

The above exception was the direct cause of the following exception:

Traceback (most recent call last):
  File "C:\Users\glebg\AppData\Roaming\Python\Python38\site-packages\discord\client.py", line 521, in connect
    self.ws = await asyncio.wait_for(coro, timeout=60.0)
  File "C:\Users\glebg\AppData\Local\Programs\Python\Python38-32\lib\asyncio\tasks.py", line 483, in wait_for
    return fut.result()
  File "C:\Users\glebg\AppData\Roaming\Python\Python38\site-packages\discord\gateway.py", line 254, in from_client
    gateway = gateway or await client.http.get_gateway()
  File "C:\Users\glebg\AppData\Roaming\Python\Python38\site-packages\discord\http.py", line 907, in get_gateway
    data = await self.request(Route('GET', '/gateway'))
  File "C:\Users\glebg\AppData\Roaming\Python\Python38\site-packages\discord\http.py", line 185, in request
    async with self.__session.request(method, url, **kwargs) as r:
  File "C:\Users\glebg\AppData\Roaming\Python\Python38\site-packages\aiohttp\client.py", line 1012, in __aenter__
    self._resp = await self._coro
  File "C:\Users\glebg\AppData\Roaming\Python\Python38\site-packages\aiohttp\client.py", line 480, in _request
    conn = await self._connector.connect(
  File "C:\Users\glebg\AppData\Roaming\Python\Python38\site-packages\aiohttp\connector.py", line 523, in connect
    proto = await self._create_connection(req, traces, timeout)
  File "C:\Users\glebg\AppData\Roaming\Python\Python38\site-packages\aiohttp\connector.py", line 858, in _create_connection
    _, proto = await self._create_direct_connection(
  File "C:\Users\glebg\AppData\Roaming\Python\Python38\site-packages\aiohttp\connector.py", line 971, in _create_direct_connection
    raise ClientConnectorError(req.connection_key, exc) from exc
aiohttp.client_exceptions.ClientConnectorError: Cannot connect to host discord.com:443 ssl:default [getaddrinfo failed]
2021-04-18 17:36:50,438 | ERROR | discord.client | Attempting a reconnect in 0.73s
Traceback (most recent call last):
  File "C:\Users\glebg\AppData\Roaming\Python\Python38\site-packages\aiohttp\connector.py", line 964, in _create_direct_connection
    hosts = await asyncio.shield(self._resolve_host(
  File "C:\Users\glebg\AppData\Roaming\Python\Python38\site-packages\aiohttp\connector.py", line 829, in _resolve_host
    addrs = await \
  File "C:\Users\glebg\AppData\Roaming\Python\Python38\site-packages\aiohttp\resolver.py", line 29, in resolve
    infos = await self._loop.getaddrinfo(
  File "C:\Users\glebg\AppData\Local\Programs\Python\Python38-32\lib\asyncio\base_events.py", line 825, in getaddrinfo
    return await self.run_in_executor(
  File "C:\Users\glebg\AppData\Local\Programs\Python\Python38-32\lib\concurrent\futures\thread.py", line 57, in run
    result = self.fn(*self.args, **self.kwargs)
  File "C:\Users\glebg\AppData\Local\Programs\Python\Python38-32\lib\socket.py", line 918, in getaddrinfo
    for res in _socket.getaddrinfo(host, port, family, type, proto, flags):
socket.gaierror: [Errno 11001] getaddrinfo failed

The above exception was the direct cause of the following exception:

Traceback (most recent call last):
  File "C:\Users\glebg\AppData\Roaming\Python\Python38\site-packages\discord\client.py", line 521, in connect
    self.ws = await asyncio.wait_for(coro, timeout=60.0)
  File "C:\Users\glebg\AppData\Local\Programs\Python\Python38-32\lib\asyncio\tasks.py", line 483, in wait_for
    return fut.result()
  File "C:\Users\glebg\AppData\Roaming\Python\Python38\site-packages\discord\gateway.py", line 254, in from_client
    gateway = gateway or await client.http.get_gateway()
  File "C:\Users\glebg\AppData\Roaming\Python\Python38\site-packages\discord\http.py", line 907, in get_gateway
    data = await self.request(Route('GET', '/gateway'))
  File "C:\Users\glebg\AppData\Roaming\Python\Python38\site-packages\discord\http.py", line 185, in request
    async with self.__session.request(method, url, **kwargs) as r:
  File "C:\Users\glebg\AppData\Roaming\Python\Python38\site-packages\aiohttp\client.py", line 1012, in __aenter__
    self._resp = await self._coro
  File "C:\Users\glebg\AppData\Roaming\Python\Python38\site-packages\aiohttp\client.py", line 480, in _request
    conn = await self._connector.connect(
  File "C:\Users\glebg\AppData\Roaming\Python\Python38\site-packages\aiohttp\connector.py", line 523, in connect
    proto = await self._create_connection(req, traces, timeout)
  File "C:\Users\glebg\AppData\Roaming\Python\Python38\site-packages\aiohttp\connector.py", line 858, in _create_connection
    _, proto = await self._create_direct_connection(
  File "C:\Users\glebg\AppData\Roaming\Python\Python38\site-packages\aiohttp\connector.py", line 971, in _create_direct_connection
    raise ClientConnectorError(req.connection_key, exc) from exc
aiohttp.client_exceptions.ClientConnectorError: Cannot connect to host discord.com:443 ssl:default [getaddrinfo failed]
2021-04-18 17:36:51,173 | ERROR | discord.client | Attempting a reconnect in 7.21s
Traceback (most recent call last):
  File "C:\Users\glebg\AppData\Roaming\Python\Python38\site-packages\aiohttp\connector.py", line 964, in _create_direct_connection
    hosts = await asyncio.shield(self._resolve_host(
  File "C:\Users\glebg\AppData\Roaming\Python\Python38\site-packages\aiohttp\connector.py", line 829, in _resolve_host
    addrs = await \
  File "C:\Users\glebg\AppData\Roaming\Python\Python38\site-packages\aiohttp\resolver.py", line 29, in resolve
    infos = await self._loop.getaddrinfo(
  File "C:\Users\glebg\AppData\Local\Programs\Python\Python38-32\lib\asyncio\base_events.py", line 825, in getaddrinfo
    return await self.run_in_executor(
  File "C:\Users\glebg\AppData\Local\Programs\Python\Python38-32\lib\concurrent\futures\thread.py", line 57, in run
    result = self.fn(*self.args, **self.kwargs)
  File "C:\Users\glebg\AppData\Local\Programs\Python\Python38-32\lib\socket.py", line 918, in getaddrinfo
    for res in _socket.getaddrinfo(host, port, family, type, proto, flags):
socket.gaierror: [Errno 11001] getaddrinfo failed

The above exception was the direct cause of the following exception:

Traceback (most recent call last):
  File "C:\Users\glebg\AppData\Roaming\Python\Python38\site-packages\discord\client.py", line 521, in connect
    self.ws = await asyncio.wait_for(coro, timeout=60.0)
  File "C:\Users\glebg\AppData\Local\Programs\Python\Python38-32\lib\asyncio\tasks.py", line 483, in wait_for
    return fut.result()
  File "C:\Users\glebg\AppData\Roaming\Python\Python38\site-packages\discord\gateway.py", line 254, in from_client
    gateway = gateway or await client.http.get_gateway()
  File "C:\Users\glebg\AppData\Roaming\Python\Python38\site-packages\discord\http.py", line 907, in get_gateway
    data = await self.request(Route('GET', '/gateway'))
  File "C:\Users\glebg\AppData\Roaming\Python\Python38\site-packages\discord\http.py", line 185, in request
    async with self.__session.request(method, url, **kwargs) as r:
  File "C:\Users\glebg\AppData\Roaming\Python\Python38\site-packages\aiohttp\client.py", line 1012, in __aenter__
    self._resp = await self._coro
  File "C:\Users\glebg\AppData\Roaming\Python\Python38\site-packages\aiohttp\client.py", line 480, in _request
    conn = await self._connector.connect(
  File "C:\Users\glebg\AppData\Roaming\Python\Python38\site-packages\aiohttp\connector.py", line 523, in connect
    proto = await self._create_connection(req, traces, timeout)
  File "C:\Users\glebg\AppData\Roaming\Python\Python38\site-packages\aiohttp\connector.py", line 858, in _create_connection
    _, proto = await self._create_direct_connection(
  File "C:\Users\glebg\AppData\Roaming\Python\Python38\site-packages\aiohttp\connector.py", line 971, in _create_direct_connection
    raise ClientConnectorError(req.connection_key, exc) from exc
aiohttp.client_exceptions.ClientConnectorError: Cannot connect to host discord.com:443 ssl:default [getaddrinfo failed]
2021-04-18 17:36:58,389 | ERROR | discord.client | Attempting a reconnect in 7.98s
Traceback (most recent call last):
  File "C:\Users\glebg\AppData\Roaming\Python\Python38\site-packages\aiohttp\connector.py", line 964, in _create_direct_connection
    hosts = await asyncio.shield(self._resolve_host(
  File "C:\Users\glebg\AppData\Roaming\Python\Python38\site-packages\aiohttp\connector.py", line 829, in _resolve_host
    addrs = await \
  File "C:\Users\glebg\AppData\Roaming\Python\Python38\site-packages\aiohttp\resolver.py", line 29, in resolve
    infos = await self._loop.getaddrinfo(
  File "C:\Users\glebg\AppData\Local\Programs\Python\Python38-32\lib\asyncio\base_events.py", line 825, in getaddrinfo
    return await self.run_in_executor(
  File "C:\Users\glebg\AppData\Local\Programs\Python\Python38-32\lib\concurrent\futures\thread.py", line 57, in run
    result = self.fn(*self.args, **self.kwargs)
  File "C:\Users\glebg\AppData\Local\Programs\Python\Python38-32\lib\socket.py", line 918, in getaddrinfo
    for res in _socket.getaddrinfo(host, port, family, type, proto, flags):
socket.gaierror: [Errno 11001] getaddrinfo failed

The above exception was the direct cause of the following exception:

Traceback (most recent call last):
  File "C:\Users\glebg\AppData\Roaming\Python\Python38\site-packages\discord\client.py", line 521, in connect
    self.ws = await asyncio.wait_for(coro, timeout=60.0)
  File "C:\Users\glebg\AppData\Local\Programs\Python\Python38-32\lib\asyncio\tasks.py", line 483, in wait_for
    return fut.result()
  File "C:\Users\glebg\AppData\Roaming\Python\Python38\site-packages\discord\gateway.py", line 254, in from_client
    gateway = gateway or await client.http.get_gateway()
  File "C:\Users\glebg\AppData\Roaming\Python\Python38\site-packages\discord\http.py", line 907, in get_gateway
    data = await self.request(Route('GET', '/gateway'))
  File "C:\Users\glebg\AppData\Roaming\Python\Python38\site-packages\discord\http.py", line 185, in request
    async with self.__session.request(method, url, **kwargs) as r:
  File "C:\Users\glebg\AppData\Roaming\Python\Python38\site-packages\aiohttp\client.py", line 1012, in __aenter__
    self._resp = await self._coro
  File "C:\Users\glebg\AppData\Roaming\Python\Python38\site-packages\aiohttp\client.py", line 480, in _request
    conn = await self._connector.connect(
  File "C:\Users\glebg\AppData\Roaming\Python\Python38\site-packages\aiohttp\connector.py", line 523, in connect
    proto = await self._create_connection(req, traces, timeout)
  File "C:\Users\glebg\AppData\Roaming\Python\Python38\site-packages\aiohttp\connector.py", line 858, in _create_connection
    _, proto = await self._create_direct_connection(
  File "C:\Users\glebg\AppData\Roaming\Python\Python38\site-packages\aiohttp\connector.py", line 971, in _create_direct_connection
    raise ClientConnectorError(req.connection_key, exc) from exc
aiohttp.client_exceptions.ClientConnectorError: Cannot connect to host discord.com:443 ssl:default [getaddrinfo failed]
2021-04-18 17:37:07,122 | INFO | discord.gateway | Shard ID None has sent the RESUME payload.
2021-04-18 17:37:07,324 | INFO | discord.gateway | Shard ID None session has been invalidated.
2021-04-18 17:37:07,530 | INFO | discord.client | Got a request to IDENTIFY the websocket.
2021-04-18 17:37:12,962 | INFO | discord.gateway | Shard ID None has sent the IDENTIFY payload.
2021-04-18 17:37:13,218 | INFO | discord.gateway | Shard ID None has connected to Gateway: ["gateway-prd-main-n5rg",{"micros":53505,"calls":["discord-sessions-prd-2-36",{"micros":49091,"calls":["start_session",{"micros":31393,"calls":["api-prd-main-cpdr",{"micros":28727,"calls":["get_user",{"micros":3781},"add_authorized_ip",{"micros":1511},"get_guilds",{"micros":4764},"coros_wait",{"micros":8}]}]},"guilds_connect",{"micros":2,"calls":[]},"presence_connect",{"micros":1,"calls":[]}]}]}] (Session ID: 47346fc10f8468174c59110bc0602a15).
2021-04-18 17:37:15,231 | INFO | discord | Bot ready to use!
2021-04-18 19:03:54,960 | INFO | discord.client | Got a request to RESUME the websocket.
2021-04-18 19:03:55,848 | INFO | discord.gateway | Shard ID None has sent the RESUME payload.
2021-04-18 19:03:56,062 | INFO | discord.gateway | Shard ID None has successfully RESUMED session 47346fc10f8468174c59110bc0602a15 under trace ["gateway-prd-main-vpbb",{"micros":2145,"calls":["discord-sessions-prd-2-36",{"micros":14}]}].
2021-04-18 21:08:35,048 | INFO | discord | Russian roulette started time:25 min, from: <@532157271531061255>
2021-04-18 21:33:34,550 | INFO | discord.voice_client | Connecting to voice...
2021-04-18 21:33:34,552 | INFO | discord.voice_client | Starting voice handshake...
2021-04-18 21:33:34,899 | INFO | discord.voice_client | Voice handshake complete. Endpoint found russia677.discord.media (IP: None)
2021-04-18 21:33:35,335 | INFO | discord.gateway | selected the voice protocol for use (xsalsa20_poly1305_lite)
2021-04-18 21:33:35,384 | INFO | discord.gateway | received secret key for voice connection
2021-04-18 21:33:44,169 | INFO | discord.voice_client | Disconnecting from voice normally, close code 4014.
2021-04-18 21:33:44,169 | INFO | discord.voice_client | The voice handshake is being terminated for Channel ID 814716051652345928 (Guild ID 731080187596374087)
2021-04-18 21:33:44,169 | INFO | discord.voice_client | The voice client has been removed for Channel ID 814716051652345928 (Guild ID 731080187596374087)
2021-04-18 21:33:44,176 | INFO | discord.player | Preparing to terminate ffmpeg process 16240.
2021-04-18 21:33:44,176 | INFO | discord.player | ffmpeg process 16240 has not terminated. Waiting to terminate...
2021-04-18 21:33:44,190 | INFO | discord.player | ffmpeg process 16240 should have terminated with a return code of 1.
2021-04-18 21:33:44,254 | INFO | discord | Roullet shoot to: Bot Of Death
2021-04-18 21:46:36,596 | INFO | discord.client | Got a request to RESUME the websocket.
2021-04-18 21:46:37,292 | INFO | discord.gateway | Shard ID None has sent the RESUME payload.
2021-04-18 21:46:37,495 | INFO | discord.gateway | Shard ID None has successfully RESUMED session 47346fc10f8468174c59110bc0602a15 under trace ["gateway-prd-main-0546",{"micros":2933,"calls":["discord-sessions-prd-2-36",{"micros":14}]}].
2021-04-18 21:58:34,550 | INFO | discord.voice_client | Connecting to voice...
2021-04-18 21:58:34,550 | INFO | discord.voice_client | Starting voice handshake...
2021-04-18 21:58:34,881 | INFO | discord.voice_client | Voice handshake complete. Endpoint found russia677.discord.media (IP: None)
2021-04-18 21:58:35,334 | INFO | discord.gateway | selected the voice protocol for use (xsalsa20_poly1305_lite)
2021-04-18 21:58:35,386 | INFO | discord.gateway | received secret key for voice connection
2021-04-18 21:58:43,567 | INFO | discord | Roullet shoot to: CeV
2021-04-18 21:58:44,043 | INFO | discord.player | Preparing to terminate ffmpeg process 14900.
2021-04-18 21:58:44,043 | INFO | discord.player | ffmpeg process 14900 successfully terminated with return code of 0.
2021-04-18 21:59:57,276 | INFO | discord.voice_client | The voice handshake is being terminated for Channel ID 814716051652345928 (Guild ID 731080187596374087)
2021-04-18 21:59:57,277 | INFO | discord.voice_client | The voice client has been removed for Channel ID 814716051652345928 (Guild ID 731080187596374087)
2021-04-18 21:59:57,279 | INFO | discord.voice_client | Disconnecting from voice normally, close code 1000.
2021-04-18 21:59:57,666 | INFO | discord | Russian Roulette stopped by: <@532157271531061255>
2021-04-18 22:16:22,556 | INFO | discord.gateway | Websocket closed with 1006, attempting a reconnect.
2021-04-18 22:16:22,556 | INFO | discord.client | Got a request to RESUME the websocket.
2021-04-18 22:16:22,584 | ERROR | discord.client | Attempting a reconnect in 0.06s
Traceback (most recent call last):
  File "C:\Users\glebg\AppData\Roaming\Python\Python38\site-packages\aiohttp\connector.py", line 964, in _create_direct_connection
    hosts = await asyncio.shield(self._resolve_host(
  File "C:\Users\glebg\AppData\Roaming\Python\Python38\site-packages\aiohttp\connector.py", line 829, in _resolve_host
    addrs = await \
  File "C:\Users\glebg\AppData\Roaming\Python\Python38\site-packages\aiohttp\resolver.py", line 29, in resolve
    infos = await self._loop.getaddrinfo(
  File "C:\Users\glebg\AppData\Local\Programs\Python\Python38-32\lib\asyncio\base_events.py", line 825, in getaddrinfo
    return await self.run_in_executor(
  File "C:\Users\glebg\AppData\Local\Programs\Python\Python38-32\lib\concurrent\futures\thread.py", line 57, in run
    result = self.fn(*self.args, **self.kwargs)
  File "C:\Users\glebg\AppData\Local\Programs\Python\Python38-32\lib\socket.py", line 918, in getaddrinfo
    for res in _socket.getaddrinfo(host, port, family, type, proto, flags):
socket.gaierror: [Errno 11001] getaddrinfo failed

The above exception was the direct cause of the following exception:

Traceback (most recent call last):
  File "C:\Users\glebg\AppData\Roaming\Python\Python38\site-packages\discord\client.py", line 521, in connect
    self.ws = await asyncio.wait_for(coro, timeout=60.0)
  File "C:\Users\glebg\AppData\Local\Programs\Python\Python38-32\lib\asyncio\tasks.py", line 483, in wait_for
    return fut.result()
  File "C:\Users\glebg\AppData\Roaming\Python\Python38\site-packages\discord\gateway.py", line 254, in from_client
    gateway = gateway or await client.http.get_gateway()
  File "C:\Users\glebg\AppData\Roaming\Python\Python38\site-packages\discord\http.py", line 907, in get_gateway
    data = await self.request(Route('GET', '/gateway'))
  File "C:\Users\glebg\AppData\Roaming\Python\Python38\site-packages\discord\http.py", line 185, in request
    async with self.__session.request(method, url, **kwargs) as r:
  File "C:\Users\glebg\AppData\Roaming\Python\Python38\site-packages\aiohttp\client.py", line 1012, in __aenter__
    self._resp = await self._coro
  File "C:\Users\glebg\AppData\Roaming\Python\Python38\site-packages\aiohttp\client.py", line 480, in _request
    conn = await self._connector.connect(
  File "C:\Users\glebg\AppData\Roaming\Python\Python38\site-packages\aiohttp\connector.py", line 523, in connect
    proto = await self._create_connection(req, traces, timeout)
  File "C:\Users\glebg\AppData\Roaming\Python\Python38\site-packages\aiohttp\connector.py", line 858, in _create_connection
    _, proto = await self._create_direct_connection(
  File "C:\Users\glebg\AppData\Roaming\Python\Python38\site-packages\aiohttp\connector.py", line 971, in _create_direct_connection
    raise ClientConnectorError(req.connection_key, exc) from exc
aiohttp.client_exceptions.ClientConnectorError: Cannot connect to host discord.com:443 ssl:default [getaddrinfo failed]
2021-04-18 22:16:22,826 | ERROR | discord.client | Attempting a reconnect in 2.87s
Traceback (most recent call last):
  File "C:\Users\glebg\AppData\Roaming\Python\Python38\site-packages\aiohttp\connector.py", line 964, in _create_direct_connection
    hosts = await asyncio.shield(self._resolve_host(
  File "C:\Users\glebg\AppData\Roaming\Python\Python38\site-packages\aiohttp\connector.py", line 829, in _resolve_host
    addrs = await \
  File "C:\Users\glebg\AppData\Roaming\Python\Python38\site-packages\aiohttp\resolver.py", line 29, in resolve
    infos = await self._loop.getaddrinfo(
  File "C:\Users\glebg\AppData\Local\Programs\Python\Python38-32\lib\asyncio\base_events.py", line 825, in getaddrinfo
    return await self.run_in_executor(
  File "C:\Users\glebg\AppData\Local\Programs\Python\Python38-32\lib\concurrent\futures\thread.py", line 57, in run
    result = self.fn(*self.args, **self.kwargs)
  File "C:\Users\glebg\AppData\Local\Programs\Python\Python38-32\lib\socket.py", line 918, in getaddrinfo
    for res in _socket.getaddrinfo(host, port, family, type, proto, flags):
socket.gaierror: [Errno 11001] getaddrinfo failed

The above exception was the direct cause of the following exception:

Traceback (most recent call last):
  File "C:\Users\glebg\AppData\Roaming\Python\Python38\site-packages\discord\client.py", line 521, in connect
    self.ws = await asyncio.wait_for(coro, timeout=60.0)
  File "C:\Users\glebg\AppData\Local\Programs\Python\Python38-32\lib\asyncio\tasks.py", line 483, in wait_for
    return fut.result()
  File "C:\Users\glebg\AppData\Roaming\Python\Python38\site-packages\discord\gateway.py", line 254, in from_client
    gateway = gateway or await client.http.get_gateway()
  File "C:\Users\glebg\AppData\Roaming\Python\Python38\site-packages\discord\http.py", line 907, in get_gateway
    data = await self.request(Route('GET', '/gateway'))
  File "C:\Users\glebg\AppData\Roaming\Python\Python38\site-packages\discord\http.py", line 185, in request
    async with self.__session.request(method, url, **kwargs) as r:
  File "C:\Users\glebg\AppData\Roaming\Python\Python38\site-packages\aiohttp\client.py", line 1012, in __aenter__
    self._resp = await self._coro
  File "C:\Users\glebg\AppData\Roaming\Python\Python38\site-packages\aiohttp\client.py", line 480, in _request
    conn = await self._connector.connect(
  File "C:\Users\glebg\AppData\Roaming\Python\Python38\site-packages\aiohttp\connector.py", line 523, in connect
    proto = await self._create_connection(req, traces, timeout)
  File "C:\Users\glebg\AppData\Roaming\Python\Python38\site-packages\aiohttp\connector.py", line 858, in _create_connection
    _, proto = await self._create_direct_connection(
  File "C:\Users\glebg\AppData\Roaming\Python\Python38\site-packages\aiohttp\connector.py", line 971, in _create_direct_connection
    raise ClientConnectorError(req.connection_key, exc) from exc
aiohttp.client_exceptions.ClientConnectorError: Cannot connect to host discord.com:443 ssl:default [getaddrinfo failed]
2021-04-19 14:42:36,143 | ERROR | discord.client | Attempting a reconnect in 0.37s
Traceback (most recent call last):
  File "C:\Users\glebg\AppData\Roaming\Python\Python38\site-packages\aiohttp\connector.py", line 964, in _create_direct_connection
    hosts = await asyncio.shield(self._resolve_host(
  File "C:\Users\glebg\AppData\Roaming\Python\Python38\site-packages\aiohttp\connector.py", line 829, in _resolve_host
    addrs = await \
  File "C:\Users\glebg\AppData\Roaming\Python\Python38\site-packages\aiohttp\resolver.py", line 29, in resolve
    infos = await self._loop.getaddrinfo(
  File "C:\Users\glebg\AppData\Local\Programs\Python\Python38-32\lib\asyncio\base_events.py", line 825, in getaddrinfo
    return await self.run_in_executor(
  File "C:\Users\glebg\AppData\Local\Programs\Python\Python38-32\lib\concurrent\futures\thread.py", line 57, in run
    result = self.fn(*self.args, **self.kwargs)
  File "C:\Users\glebg\AppData\Local\Programs\Python\Python38-32\lib\socket.py", line 918, in getaddrinfo
    for res in _socket.getaddrinfo(host, port, family, type, proto, flags):
socket.gaierror: [Errno 11001] getaddrinfo failed

The above exception was the direct cause of the following exception:

Traceback (most recent call last):
  File "C:\Users\glebg\AppData\Roaming\Python\Python38\site-packages\discord\client.py", line 521, in connect
    self.ws = await asyncio.wait_for(coro, timeout=60.0)
  File "C:\Users\glebg\AppData\Local\Programs\Python\Python38-32\lib\asyncio\tasks.py", line 483, in wait_for
    return fut.result()
  File "C:\Users\glebg\AppData\Roaming\Python\Python38\site-packages\discord\gateway.py", line 254, in from_client
    gateway = gateway or await client.http.get_gateway()
  File "C:\Users\glebg\AppData\Roaming\Python\Python38\site-packages\discord\http.py", line 907, in get_gateway
    data = await self.request(Route('GET', '/gateway'))
  File "C:\Users\glebg\AppData\Roaming\Python\Python38\site-packages\discord\http.py", line 185, in request
    async with self.__session.request(method, url, **kwargs) as r:
  File "C:\Users\glebg\AppData\Roaming\Python\Python38\site-packages\aiohttp\client.py", line 1012, in __aenter__
    self._resp = await self._coro
  File "C:\Users\glebg\AppData\Roaming\Python\Python38\site-packages\aiohttp\client.py", line 480, in _request
    conn = await self._connector.connect(
  File "C:\Users\glebg\AppData\Roaming\Python\Python38\site-packages\aiohttp\connector.py", line 523, in connect
    proto = await self._create_connection(req, traces, timeout)
  File "C:\Users\glebg\AppData\Roaming\Python\Python38\site-packages\aiohttp\connector.py", line 858, in _create_connection
    _, proto = await self._create_direct_connection(
  File "C:\Users\glebg\AppData\Roaming\Python\Python38\site-packages\aiohttp\connector.py", line 971, in _create_direct_connection
    raise ClientConnectorError(req.connection_key, exc) from exc
aiohttp.client_exceptions.ClientConnectorError: Cannot connect to host discord.com:443 ssl:default [getaddrinfo failed]
2021-04-19 14:42:36,518 | ERROR | discord.client | Attempting a reconnect in 0.30s
Traceback (most recent call last):
  File "C:\Users\glebg\AppData\Roaming\Python\Python38\site-packages\aiohttp\connector.py", line 964, in _create_direct_connection
    hosts = await asyncio.shield(self._resolve_host(
  File "C:\Users\glebg\AppData\Roaming\Python\Python38\site-packages\aiohttp\connector.py", line 829, in _resolve_host
    addrs = await \
  File "C:\Users\glebg\AppData\Roaming\Python\Python38\site-packages\aiohttp\resolver.py", line 29, in resolve
    infos = await self._loop.getaddrinfo(
  File "C:\Users\glebg\AppData\Local\Programs\Python\Python38-32\lib\asyncio\base_events.py", line 825, in getaddrinfo
    return await self.run_in_executor(
  File "C:\Users\glebg\AppData\Local\Programs\Python\Python38-32\lib\concurrent\futures\thread.py", line 57, in run
    result = self.fn(*self.args, **self.kwargs)
  File "C:\Users\glebg\AppData\Local\Programs\Python\Python38-32\lib\socket.py", line 918, in getaddrinfo
    for res in _socket.getaddrinfo(host, port, family, type, proto, flags):
socket.gaierror: [Errno 11001] getaddrinfo failed

The above exception was the direct cause of the following exception:

Traceback (most recent call last):
  File "C:\Users\glebg\AppData\Roaming\Python\Python38\site-packages\discord\client.py", line 521, in connect
    self.ws = await asyncio.wait_for(coro, timeout=60.0)
  File "C:\Users\glebg\AppData\Local\Programs\Python\Python38-32\lib\asyncio\tasks.py", line 483, in wait_for
    return fut.result()
  File "C:\Users\glebg\AppData\Roaming\Python\Python38\site-packages\discord\gateway.py", line 254, in from_client
    gateway = gateway or await client.http.get_gateway()
  File "C:\Users\glebg\AppData\Roaming\Python\Python38\site-packages\discord\http.py", line 907, in get_gateway
    data = await self.request(Route('GET', '/gateway'))
  File "C:\Users\glebg\AppData\Roaming\Python\Python38\site-packages\discord\http.py", line 185, in request
    async with self.__session.request(method, url, **kwargs) as r:
  File "C:\Users\glebg\AppData\Roaming\Python\Python38\site-packages\aiohttp\client.py", line 1012, in __aenter__
    self._resp = await self._coro
  File "C:\Users\glebg\AppData\Roaming\Python\Python38\site-packages\aiohttp\client.py", line 480, in _request
    conn = await self._connector.connect(
  File "C:\Users\glebg\AppData\Roaming\Python\Python38\site-packages\aiohttp\connector.py", line 523, in connect
    proto = await self._create_connection(req, traces, timeout)
  File "C:\Users\glebg\AppData\Roaming\Python\Python38\site-packages\aiohttp\connector.py", line 858, in _create_connection
    _, proto = await self._create_direct_connection(
  File "C:\Users\glebg\AppData\Roaming\Python\Python38\site-packages\aiohttp\connector.py", line 971, in _create_direct_connection
    raise ClientConnectorError(req.connection_key, exc) from exc
aiohttp.client_exceptions.ClientConnectorError: Cannot connect to host discord.com:443 ssl:default [getaddrinfo failed]
2021-04-19 14:42:36,824 | ERROR | discord.client | Attempting a reconnect in 6.22s
Traceback (most recent call last):
  File "C:\Users\glebg\AppData\Roaming\Python\Python38\site-packages\aiohttp\connector.py", line 964, in _create_direct_connection
    hosts = await asyncio.shield(self._resolve_host(
  File "C:\Users\glebg\AppData\Roaming\Python\Python38\site-packages\aiohttp\connector.py", line 829, in _resolve_host
    addrs = await \
  File "C:\Users\glebg\AppData\Roaming\Python\Python38\site-packages\aiohttp\resolver.py", line 29, in resolve
    infos = await self._loop.getaddrinfo(
  File "C:\Users\glebg\AppData\Local\Programs\Python\Python38-32\lib\asyncio\base_events.py", line 825, in getaddrinfo
    return await self.run_in_executor(
  File "C:\Users\glebg\AppData\Local\Programs\Python\Python38-32\lib\concurrent\futures\thread.py", line 57, in run
    result = self.fn(*self.args, **self.kwargs)
  File "C:\Users\glebg\AppData\Local\Programs\Python\Python38-32\lib\socket.py", line 918, in getaddrinfo
    for res in _socket.getaddrinfo(host, port, family, type, proto, flags):
socket.gaierror: [Errno 11001] getaddrinfo failed

The above exception was the direct cause of the following exception:

Traceback (most recent call last):
  File "C:\Users\glebg\AppData\Roaming\Python\Python38\site-packages\discord\client.py", line 521, in connect
    self.ws = await asyncio.wait_for(coro, timeout=60.0)
  File "C:\Users\glebg\AppData\Local\Programs\Python\Python38-32\lib\asyncio\tasks.py", line 483, in wait_for
    return fut.result()
  File "C:\Users\glebg\AppData\Roaming\Python\Python38\site-packages\discord\gateway.py", line 254, in from_client
    gateway = gateway or await client.http.get_gateway()
  File "C:\Users\glebg\AppData\Roaming\Python\Python38\site-packages\discord\http.py", line 907, in get_gateway
    data = await self.request(Route('GET', '/gateway'))
  File "C:\Users\glebg\AppData\Roaming\Python\Python38\site-packages\discord\http.py", line 185, in request
    async with self.__session.request(method, url, **kwargs) as r:
  File "C:\Users\glebg\AppData\Roaming\Python\Python38\site-packages\aiohttp\client.py", line 1012, in __aenter__
    self._resp = await self._coro
  File "C:\Users\glebg\AppData\Roaming\Python\Python38\site-packages\aiohttp\client.py", line 480, in _request
    conn = await self._connector.connect(
  File "C:\Users\glebg\AppData\Roaming\Python\Python38\site-packages\aiohttp\connector.py", line 523, in connect
    proto = await self._create_connection(req, traces, timeout)
  File "C:\Users\glebg\AppData\Roaming\Python\Python38\site-packages\aiohttp\connector.py", line 858, in _create_connection
    _, proto = await self._create_direct_connection(
  File "C:\Users\glebg\AppData\Roaming\Python\Python38\site-packages\aiohttp\connector.py", line 971, in _create_direct_connection
    raise ClientConnectorError(req.connection_key, exc) from exc
aiohttp.client_exceptions.ClientConnectorError: Cannot connect to host discord.com:443 ssl:default [getaddrinfo failed]
2021-04-19 14:42:43,050 | ERROR | discord.client | Attempting a reconnect in 6.87s
Traceback (most recent call last):
  File "C:\Users\glebg\AppData\Roaming\Python\Python38\site-packages\aiohttp\connector.py", line 964, in _create_direct_connection
    hosts = await asyncio.shield(self._resolve_host(
  File "C:\Users\glebg\AppData\Roaming\Python\Python38\site-packages\aiohttp\connector.py", line 829, in _resolve_host
    addrs = await \
  File "C:\Users\glebg\AppData\Roaming\Python\Python38\site-packages\aiohttp\resolver.py", line 29, in resolve
    infos = await self._loop.getaddrinfo(
  File "C:\Users\glebg\AppData\Local\Programs\Python\Python38-32\lib\asyncio\base_events.py", line 825, in getaddrinfo
    return await self.run_in_executor(
  File "C:\Users\glebg\AppData\Local\Programs\Python\Python38-32\lib\concurrent\futures\thread.py", line 57, in run
    result = self.fn(*self.args, **self.kwargs)
  File "C:\Users\glebg\AppData\Local\Programs\Python\Python38-32\lib\socket.py", line 918, in getaddrinfo
    for res in _socket.getaddrinfo(host, port, family, type, proto, flags):
socket.gaierror: [Errno 11001] getaddrinfo failed

The above exception was the direct cause of the following exception:

Traceback (most recent call last):
  File "C:\Users\glebg\AppData\Roaming\Python\Python38\site-packages\discord\client.py", line 521, in connect
    self.ws = await asyncio.wait_for(coro, timeout=60.0)
  File "C:\Users\glebg\AppData\Local\Programs\Python\Python38-32\lib\asyncio\tasks.py", line 483, in wait_for
    return fut.result()
  File "C:\Users\glebg\AppData\Roaming\Python\Python38\site-packages\discord\gateway.py", line 254, in from_client
    gateway = gateway or await client.http.get_gateway()
  File "C:\Users\glebg\AppData\Roaming\Python\Python38\site-packages\discord\http.py", line 907, in get_gateway
    data = await self.request(Route('GET', '/gateway'))
  File "C:\Users\glebg\AppData\Roaming\Python\Python38\site-packages\discord\http.py", line 185, in request
    async with self.__session.request(method, url, **kwargs) as r:
  File "C:\Users\glebg\AppData\Roaming\Python\Python38\site-packages\aiohttp\client.py", line 1012, in __aenter__
    self._resp = await self._coro
  File "C:\Users\glebg\AppData\Roaming\Python\Python38\site-packages\aiohttp\client.py", line 480, in _request
    conn = await self._connector.connect(
  File "C:\Users\glebg\AppData\Roaming\Python\Python38\site-packages\aiohttp\connector.py", line 523, in connect
    proto = await self._create_connection(req, traces, timeout)
  File "C:\Users\glebg\AppData\Roaming\Python\Python38\site-packages\aiohttp\connector.py", line 858, in _create_connection
    _, proto = await self._create_direct_connection(
  File "C:\Users\glebg\AppData\Roaming\Python\Python38\site-packages\aiohttp\connector.py", line 971, in _create_direct_connection
    raise ClientConnectorError(req.connection_key, exc) from exc
aiohttp.client_exceptions.ClientConnectorError: Cannot connect to host discord.com:443 ssl:default [getaddrinfo failed]
2021-04-19 14:42:50,602 | INFO | discord.gateway | Shard ID None has sent the RESUME payload.
2021-04-19 14:42:50,798 | INFO | discord.gateway | Shard ID None session has been invalidated.
2021-04-19 14:42:51,016 | INFO | discord.client | Got a request to IDENTIFY the websocket.
2021-04-19 14:42:56,436 | INFO | discord.gateway | Shard ID None has sent the IDENTIFY payload.
2021-04-19 14:42:56,749 | INFO | discord.gateway | Websocket closed with 4000, attempting a reconnect.
2021-04-19 14:42:56,749 | INFO | discord.client | Got a request to RESUME the websocket.
2021-04-19 14:42:57,191 | INFO | discord.gateway | Shard ID None has sent the RESUME payload.
2021-04-19 14:42:57,392 | INFO | discord.gateway | Shard ID None session has been invalidated.
2021-04-19 14:42:57,590 | INFO | discord.client | Got a request to IDENTIFY the websocket.
2021-04-19 14:43:03,024 | INFO | discord.gateway | Shard ID None has sent the IDENTIFY payload.
2021-04-19 14:43:03,339 | INFO | discord.gateway | Shard ID None has connected to Gateway: ["gateway-prd-main-pqgq",{"micros":116063,"calls":["discord-sessions-prd-2-27",{"micros":90230,"calls":["start_session",{"micros":33492,"calls":["api-prd-main-shxh",{"micros":29739,"calls":["get_user",{"micros":3873},"add_authorized_ip",{"micros":1612},"get_guilds",{"micros":5041},"coros_wait",{"micros":0}]}]},"guilds_connect",{"micros":1,"calls":[]},"presence_connect",{"micros":22162,"calls":[]}]}]}] (Session ID: 76b2bb18c5bf81788ab5c8effd9c63e0).
2021-04-19 14:43:05,959 | INFO | discord | Bot ready to use!
-----------------------------------New Session-----------------------------------
2021-04-19 17:37:21,408 | INFO | discord.client | logging in using static token
2021-04-19 17:37:22,484 | INFO | discord.gateway | Shard ID None has sent the IDENTIFY payload.
2021-04-19 17:37:22,772 | INFO | discord.gateway | Shard ID None has connected to Gateway: ["gateway-prd-main-9z8b",{"micros":85651,"calls":["discord-sessions-prd-2-76",{"micros":83027,"calls":["start_session",{"micros":44244,"calls":["api-prd-main-c30v",{"micros":40688,"calls":["get_user",{"micros":4297},"add_authorized_ip",{"micros":2512},"get_guilds",{"micros":5759},"coros_wait",{"micros":1}]}]},"guilds_connect",{"micros":1,"calls":[]},"presence_connect",{"micros":33492,"calls":[]}]}]}] (Session ID: 64cdeb735a7edc2b5548a87c2eff19d0).
2021-04-19 17:37:24,785 | INFO | discord | Bot ready to use!
2021-04-19 17:53:02,605 | INFO | discord | Wikipedia page not found! Text: я ищу что-то
2021-04-19 17:53:10,738 | INFO | discord | Wikipedia page founded, url: https://ru.wikipedia.org/wiki/%D0%A2%D0%B5%D1%81%D1%82, from: 532157271531061255
-----------------------------------New Session-----------------------------------
2021-04-19 17:53:39,120 | INFO | discord.client | logging in using static token
2021-04-19 17:53:40,030 | INFO | discord.gateway | Shard ID None has sent the IDENTIFY payload.
2021-04-19 17:53:40,278 | INFO | discord.gateway | Shard ID None has connected to Gateway: ["gateway-prd-main-r84b",{"micros":50379,"calls":["discord-sessions-prd-2-91",{"micros":48943,"calls":["start_session",{"micros":47160,"calls":["api-prd-main-grnp",{"micros":44308,"calls":["get_user",{"micros":2393},"add_authorized_ip",{"micros":1533},"get_guilds",{"micros":12493},"coros_wait",{"micros":1}]}]},"guilds_connect",{"micros":1,"calls":[]},"presence_connect",{"micros":0,"calls":[]}]}]}] (Session ID: 0d9f4d5c59a50753e46a287d844b048d).
2021-04-19 17:53:42,292 | INFO | discord | Bot ready to use!
